Workbook

Sheet scored_company_data
A1: CompanyID | B1: CompanyName | C1: Industry | D1: Region | E1: Revenue_WMA | F1: Revenue_std | G1: Revenue_cv | H1: Revenue_slope | I1: ProfitMargin_WMA | J1: ProfitMargin_std | K1: ProfitMargin_cv | L1: ProfitMargin_slope | M1: MarketCap_WMA | N1: MarketCap_std | O1: MarketCap_cv | P1: MarketCap_slope | Q1: GrowthRate_WMA | R1: GrowthRate_std | S1: GrowthRate_cv | T1: GrowthRate_slope | U1: ESG_Overall_WMA | V1: ESG_Overall_std | W1: ESG_Overall_cv | X1: ESG_Overall_slope | Y1: PriceToSales | Z1: NetIncome | AA1: PriceToEarnings | AB1: EarningsYield | AC1: Risk-AdjustedGrowth | AD1: Earnings-to-Growth | AE1: ESG_Signal-to-Noise | AF1: TARGET_SCORE
A2: 614 | B2: Company_614 | C2: Finance | D2: Asia | E2: 6451.33 | F2: 656.87 | G2: 0.1 | H2: 382.01 | I2: 3.07 | J2: 1.34 | K2: 0.44 | L2: -0.28 | M2: 3331.74 | N2: 1557.82 | O2: 0.47 | P2: 246.0 | Q2: 8.08 | R2: 6.16 | S2: 0.76 | T2: 0.66 | U2: 81.83 | V2: 0.96 | W2: 0.01 | X2: 0.53 | Y2: 0.52 | Z2: 198.06 | AA2: 16.82 | AB2: 0.06 | AC2: 1.31 | AD2: 12.82 | AE2: 53.0 | AF2: 86.87
A3: 270 | B3: Company_270 | C3: Manufacturing | D3: Asia | E3: 6194.71 | F3: 1079.41 | G3: 0.17 | H3: 681.47 | I3: 6.11 | J3: 1.31 | K3: 0.21 | L3: -0.1 | M3: 4620.89 | N3: 773.31 | O3: 0.17 | P3: 300.05 | Q3: 11.69 | R3: 5.41 | S3: 0.46 | T3: 2.26 | U3: 55.74 | V3: 0.77 | W3: 0.01 | X3: 0.39 | Y3: 0.75 | Z3: 378.5 | AA3: 12.21 | AB3: 0.08 | AC3: 2.16 | AD3: 5.65 | AE3: 39.0 | AF3: 86.77
A4: 580 | B4: Company_580 | C4: Technology | D4: Latin America | E4: 2657.58 | F4: 551.12 | G4: 0.21 | H4: 344.91 | I4: 0.91 | J4: 0.91 | K4: 1.0 | L4: -0.25 | M4: 584.87 | N4: 609.15 | O4: 1.04 | P4: -92.42 | Q4: 13.63 | R4: 7.85 | S4: 0.58 | T4: -0.92 | U4: 72.48 | V4: 1.64 | W4: 0.02 | X4: 1.02 | Y4: 0.22 | Z4: 24.18 | AA4: 24.18 | AB4: 0.04 | AC4: 1.74 | AD4: 13.93 | AE4: 51.0 | AF4: 85.72
A5: 746 | B5: Company_746 | C5: Transportation | D5: North America | E5: 1408.61 | F5: 97.2 | G5: 0.07 | H5: 52.78 | I5: 3.33 | J5: 3.68 | K5: 1.1 | L5: -2.32 | M5: 630.23 | N5: 556.45 | O5: 0.88 | P5: -322.58 | Q5: 5.84 | R5: 5.33 | S5: 0.91 | T5: 0.51 | U5: 66.07 | V5: 0.88 | W5: 0.01 | X5: 0.49 | Y5: 0.45 | Z5: 46.91 | AA5: 13.44 | AB5: 0.07 | AC5: 1.1 | AD5: 12.26 | AE5: 49.0 | AF5: 83.62
A6: 39 | B6: Company_39 | C6: Transportation | D6: Latin America | E6: 2040.6 | F6: 403.7 | G6: 0.2 | H6: 254.91 | I6: 7.29 | J6: 2.41 | K6: 0.33 | L6: 1.13 | M6: 1977.16 | N6: 750.39 | O6: 0.38 | P6: 404.01 | Q6: 13.89 | R6: 3.72 | S6: 0.27 | T6: 1.06 | U6: 52.12 | V6: 2.3 | W6: 0.04 | X6: 1.44 | Y6: 0.97 | Z6: 148.76 | AA6: 13.29 | AB6: 0.08 | AC6: 3.73 | AD6: 3.56 | AE6: 36.0 | AF6: 82.6
A7: 626 | B7: Company_626 | C7: Healthcare | D7: Europe | E7: 8166.99 | F7: 1857.64 | G7: 0.23 | H7: 1162.69 | I7: 3.11 | J7: 4.15 | K7: 1.34 | L7: -2.51 | M7: 3716.46 | N7: 3856.73 | O7: 1.04 | P7: -2379.84 | Q7: 15.84 | R7: 7.79 | S7: 0.49 | T7: 1.08 | U7: 72.33 | V7: 1.45 | W7: 0.02 | X7: 0.79 | Y7: 0.46 | Z7: 253.99 | AA7: 14.63 | AB7: 0.07 | AC7: 2.03 | AD7: 7.2 | AE7: 39.5 | AF7: 82.21
A8: 335 | B8: Company_335 | C8: Utilities | D8: Latin America | E8: 356.7 | F8: 12.65 | G8: 0.04 | H8: 7.5 | I8: 9.05 | J8: 1.71 | K8: 0.19 | L8: -1.06 | M8: 312.26 | N8: 104.44 | O8: 0.33 | P8: -52.44 | Q8: 2.52 | R8: 1.75 | S8: 0.69 | T8: 0.99 | U8: 76.96 | V8: 0.33 | W8: 0.0 | X8: 0.12 | Y8: 0.88 | Z8: 32.28 | AA8: 9.67 | AB8: 0.1 | AC8: 1.44 | AD8: 6.72 | AE8: inf | AF8: 82.07
A9: 838 | B9: Company_838 | C9: Finance | D9: Latin America | E9: 16042.84 | F9: 3265.8 | G9: 0.2 | H9: 1979.1 | I9: 2.56 | J9: 1.43 | K9: 0.56 | L9: 0.24 | M9: 5801.61 | N9: 4118.66 | O9: 0.71 | P9: 536.71 | Q9: 15.71 | R9: 7.7 | S9: 0.49 | T9: 4.03 | U9: 80.31 | V9: 2.26 | W9: 0.03 | X9: 1.37 | Y9: 0.36 | Z9: 410.7 | AA9: 14.13 | AB9: 0.07 | AC9: 2.04 | AD9: 6.92 | AE9: 45.67 | AF9: 81.99
A10: 840 | B10: Company_840 | C10: Utilities | D10: Africa | E10: 1724.13 | F10: 225.82 | G10: 0.13 | H10: 109.18 | I10: 2.25 | J10: 1.07 | K10: 0.47 | L10: -0.64 | M10: 471.95 | N10: 189.7 | O10: 0.4 | P10: -81.8 | Q10: 8.63 | R10: 11.84 | S10: 1.37 | T10: 4.15 | U10: 57.92 | V10: 0.83 | W10: 0.01 | X10: 0.51 | Y10: 0.27 | Z10: 38.79 | AA10: 12.17 | AB10: 0.08 | AC10: 0.73 | AD10: 16.69 | AE10: 51.0 | AF10: 81.68
A11: 439 | B11: Company_439 | C11: Utilities | D11: North America | E11: 949.71 | F11: 98.89 | G11: 0.1 | H11: 56.71 | I11: 8.19 | J11: 1.01 | K11: 0.12 | L11: -0.61 | M11: 763.39 | N11: 152.18 | O11: 0.2 | P11: -26.6 | Q11: 7.97 | R11: 5.64 | S11: 0.71 | T11: 1.57 | U11: 83.32 | V11: 1.85 | W11: 0.02 | X11: 1.11 | Y11: 0.8 | Z11: 77.78 | AA11: 9.81 | AB11: 0.1 | AC11: 1.41 | AD11: 6.95 | AE11: 55.5 | AF11: 81.22
A12: 689 | B12: Company_689 | C12: Finance | D12: Asia | E12: 1530.57 | F12: 244.16 | G12: 0.16 | H12: 153.88 | I12: 6.69 | J12: 2.46 | K12: 0.37 | L12: -1.12 | M12: 1508.2 | N12: 573.49 | O12: 0.38 | P12: 110.19 | Q12: 11.13 | R12: 4.32 | S12: 0.39 | T12: 1.73 | U12: 59.23 | V12: 1.79 | W12: 0.03 | X12: 1.07 | Y12: 0.99 | Z12: 102.4 | AA12: 14.73 | AB12: 0.07 | AC12: 2.58 | AD12: 5.72 | AE12: 35.67 | AF12: 80.53
A13: 744 | B13: Company_744 | C13: Transportation | D13: North America | E13: 3878.6 | F13: 336.95 | G13: 0.09 | H13: 197.31 | I13: 6.61 | J13: 2.77 | K13: 0.42 | L13: -1.49 | M13: 3097.61 | N13: 1221.5 | O13: 0.39 | P13: -278.26 | Q13: 6.29 | R13: 8.07 | S13: 1.28 | T13: -1.39 | U13: 65.65 | V13: 1.63 | W13: 0.02 | X13: 0.95 | Y13: 0.8 | Z13: 256.38 | AA13: 12.08 | AB13: 0.08 | AC13: 0.78 | AD13: 15.5 | AE13: 47.5 | AF13: 77.37
... A201: 508 | B201: Company_508 | C201: Utilities | D201: Europe | E201: 350.38 | F201: 17.72 | G201: 0.05 | H201: 8.94 | I201: 7.35 | J201: 2.03 | K201: 0.28 | L201: -1.03 | M201: 267.36 | N201: 128.8 | O201: 0.48 | P201: -57.06 | Q201: 2.77 | R201: 7.73 | S201: 2.79 | T201: 2.42 | U201: 58.4 | V201: 2.09 | W201: 0.04 | X201: 1.26 | Y201: 0.76 | Z201: 25.75 | AA201: 10.38 | AB201: 0.1 | AC201: 0.36 | AD201: 28.97 | AE201: 31.5 | AF201: 59.54
A202: 36 | B202: Company_36 | C202: Healthcare | D202: Europe | E202: 2642.85 | F202: 284.14 | G202: 0.11 | H202: 172.99 | I202: 27.65 | J202: 1.82 | K202: 0.07 | L202: 0.74 | M202: 13914.46 | N202: 3438.9 | O202: 0.25 | P202: 1801.59 | Q202: 7.47 | R202: 5.27 | S202: 0.7 | T202: 0.14 | U202: 76.24 | V202: 0.26 | W202: 0.0 | X202: -0.0 | Y202: 5.26 | Z202: 730.75 | AA202: 19.04 | AB202: 0.05 | AC202: 1.42 | AD202: 13.43 | AF202: 59.48
A203: 532 | B203: Company_532 | C203: Retail | D203: North America | E203: 441.54 | F203: 31.32 | G203: 0.07 | H203: 17.67 | I203: 10.15 | J203: 1.54 | K203: 0.15 | L203: 0.55 | M203: 782.12 | N203: 198.04 | O203: 0.25 | P203: 112.77 | Q203: 3.95 | R203: 4.92 | S203: 1.25 | T203: -2.3 | U203: 92.13 | V203: 0.65 | W203: 0.01 | X203: 0.32 | Y203: 1.77 | Z203: 44.82 | AA203: 17.45 | AB203: 0.06 | AC203: 0.8 | AD203: 21.74 | AE203: 32.0 | AF203: 59.35
A204: 153 | B204: Company_153 | C204: Consumer Goods | D204: Oceania | E204: 970.93 | F204: 57.46 | G204: 0.06 | H204: 31.64 | I204: 17.11 | J204: 3.43 | K204: 0.2 | L204: 2.08 | M204: 3312.57 | N204: 1144.21 | O204: 0.35 | P204: 579.59 | Q204: 4.62 | R204: 5.03 | S204: 1.09 | T204: -0.03 | U204: 60.64 | V204: 0.77 | W204: 0.01 | X204: 0.45 | Y204: 3.41 | Z204: 166.13 | AA204: 19.94 | AB204: 0.05 | AC204: 0.92 | AD204: 21.71 | AE204: 45.0 | AF204: 59.27
A205: 337 | B205: Company_337 | C205: Finance | D205: Africa | E205: 4885.85 | F205: 843.27 | G205: 0.17 | H205: 514.37 | I205: 25.26 | J205: 1.51 | K205: 0.06 | L205: 0.63 | M205: 20773.41 | N205: 6440.83 | O205: 0.31 | P205: 3438.98 | Q205: 12.32 | R205: 9.24 | S205: 0.75 | T205: 4.41 | U205: 70.89 | V205: 2.83 | W205: 0.04 | X205: 1.7 | Y205: 4.25 | Z205: 1234.17 | AA205: 16.83 | AB205: 0.06 | AC205: 1.33 | AD205: 12.62 | AE205: 42.5 | AF205: 59.27
A206: 901 | B206: Company_901 | C206: Consumer Goods | D206: Europe | E206: 761.95 | F206: 38.81 | G206: 0.05 | H206: 11.36 | I206: 9.51 | J206: 1.93 | K206: 0.2 | L206: 0.13 | M206: 1129.76 | N206: 346.85 | O206: 0.31 | P206: -69.24 | Q206: 2.98 | R206: 6.92 | S206: 2.32 | T206: 4.05 | U206: 65.1 | V206: 1.97 | W206: 0.03 | X206: 1.08 | Y206: 1.48 | Z206: 72.46 | AA206: 15.59 | AB206: 0.06 | AC206: 0.43 | AD206: 36.21 | AE206: 36.0 | AF206: 59.24
A207: 993 | B207: Company_993 | C207: Healthcare | D207: Latin America | E207: 6554.77 | F207: 574.3 | G207: 0.09 | H207: 356.23 | I207: 18.22 | J207: 1.62 | K207: 0.09 | L207: 0.42 | M207: 21577.87 | N207: 4673.97 | O207: 0.22 | P207: 1156.46 | Q207: 5.53 | R207: 3.48 | S207: 0.63 | T207: -1.19 | U207: 68.89 | V207: 1.87 | W207: 0.03 | X207: 0.94 | Y207: 3.29 | Z207: 1194.28 | AA207: 18.07 | AB207: 0.06 | AC207: 1.59 | AD207: 11.37 | AE207: 31.33 | AF207: 59.23
A208: 242 | B208: Company_242 | C208: Finance | D208: Latin America | E208: 351.17 | F208: 31.75 | G208: 0.09 | H208: 19.97 | I208: 7.48 | J208: 1.07 | K208: 0.14 | L208: 0.24 | M208: 396.89 | N208: 108.87 | O208: 0.27 | P208: 45.8 | Q208: 5.46 | R208: 5.87 | S208: 1.08 | T208: 2.43 | U208: 46.86 | V208: 1.01 | W208: 0.02 | X208: 0.54 | Y208: 1.13 | Z208: 26.27 | AA208: 15.11 | AB208: 0.07 | AC208: 0.93 | AD208: 16.24 | AE208: 27.0 | AF208: 59.17
A209: 252 | B209: Company_252 | C209: Consumer Goods | D209: North America | E209: 1624.88 | F209: 158.07 | G209: 0.1 | H209: 92.1 | I209: 12.53 | J209: 1.41 | K209: 0.11 | L209: 0.52 | M209: 3040.47 | N209: 596.54 | O209: 0.2 | P209: 262.25 | Q209: 4.79 | R209: 6.99 | S209: 1.46 | T209: -0.92 | U209: 69.99 | V209: 1.92 | W209: 0.03 | X209: 1.18 | Y209: 1.87 | Z209: 203.6 | AA209: 14.93 | AB209: 0.07 | AC209: 0.69 | AD209: 21.79 | AE209: 39.33 | AF209: 59.17
A210: 38 | B210: Company_38 | C210: Energy | D210: Africa | E210: 942.92 | F210: 98.11 | G210: 0.1 | H210: 59.46 | I210: 3.35 | J210: 4.75 | K210: 1.42 | L210: -2.71 | M210: 417.51 | N210: 346.17 | O210: 0.83 | P210: -182.38 | Q210: 7.62 | R210: 5.85 | S210: 0.77 | T210: -2.1 | U210: 40.77 | V210: 1.86 | W210: 0.05 | X210: 1.03 | Y210: 0.44 | Z210: 31.59 | AA210: 13.22 | AB210: 0.08 | AC210: 1.3 | AD210: 10.15 | AE210: 20.6 | AF210: 59.01
A211: 467 | B211: Company_467 | C211: Manufacturing | D211: Middle East | E211: 1108.43 | F211: 186.43 | G211: 0.17 | H211: 117.05 | I211: 9.51 | J211: 1.92 | K211: 0.2 | L211: 0.52 | M211: 1666.81 | N211: 629.88 | O211: 0.38 | P211: 363.52 | Q211: 12.49 | R211: 3.73 | S211: 0.3 | T211: -0.61 | U211: 41.35 | V211: 0.61 | W211: 0.01 | X211: 0.29 | Y211: 1.5 | Z211: 105.41 | AA211: 15.81 | AB211: 0.06 | AC211: 3.35 | AD211: 4.72 | AE211: 29.0 | AF211: 58.95
A212: 864 | B212: Company_864 | C212: Consumer Goods | D212: Africa | E212: 3011.96 | F212: 350.27 | G212: 0.12 | H212: 219.63 | I212: 13.27 | J212: 0.71 | K212: 0.05 | L212: -0.26 | M212: 6242.44 | N212: 2046.48 | O212: 0.33 | P212: 568.77 | Q212: 8.15 | R212: 2.81 | S212: 0.34 | T212: -0.47 | U212: 58.43 | V212: 2.2 | W212: 0.04 | X212: 1.39 | Y212: 2.07 | Z212: 399.69 | AA212: 15.62 | AB212: 0.06 | AC212: 2.9 | AD212: 5.38 | AE212: 34.75 | AF212: 58.94
A213: 720 | B213: Company_720 | C213: Energy | D213: Asia | E213: 11910.21 | F213: 1276.2 | G213: 0.11 | H213: 791.86 | I213: 15.21 | J213: 2.78 | K213: 0.18 | L213: 1.43 | M213: 25070.95 | N213: 6604.58 | O213: 0.26 | P213: 2812.16 | Q213: 6.81 | R213: 4.17 | S213: 0.61 | T213: -0.07 | U213: 57.68 | V213: 1.67 | W213: 0.03 | X213: 1.05 | Y213: 2.1 | Z213: 1811.54 | AA213: 13.84 | AB213: 0.07 | AC213: 1.63 | AD213: 8.47 | AE213: 35.0 | AF213: 58.8
A214: 665 | B214: Company_665 | C214: Technology | D214: Asia | E214: 10015.1 | F214: 1735.01 | G214: 0.17 | H214: 1086.36 | I214: 16.8 | J214: 1.54 | K214: 0.09 | L214: -0.33 | M214: 41189.97 | N214: 7805.13 | O214: 0.19 | P214: -68.75 | Q214: 11.35 | R214: 10.6 | S214: 0.93 | T214: 4.99 | U214: 60.61 | V214: 1.93 | W214: 0.03 | X214: 1.19 | Y214: 4.11 | Z214: 1682.54 | AA214: 24.48 | AB214: 0.04 | AC214: 1.07 | AD214: 22.86 | AE214: 39.67 | AF214: 58.7
... A375: 871 | B375: Company_871 | C375: Finance | D375: Latin America | E375: 243.68 | F375: 14.08 | G375: 0.06 | H375: -3.33 | I375: 16.98 | J375: 1.35 | K375: 0.08 | L375: 0.81 | M375: 580.01 | N375: 163.03 | O375: 0.28 | P375: 65.03 | Q375: -2.48 | R375: 8.46 | S375: -3.41 | T375: -4.5 | U375: 66.62 | V375: 1.0 | W375: 0.01 | X375: 0.6 | Y375: 2.38 | Z375: 41.38 | AA375: 14.02 | AB375: 0.07 | AC375: -0.29 | AD375: 178.16 | AE375: 60.0 | AF375: 50.03
A376: 291 | B376: Company_291 | C376: Technology | D376: Oceania | E376: 17700.79 | F376: 4699.75 | G376: 0.27 | H376: 2957.35 | I376: 10.66 | J376: 4.08 | K376: 0.38 | L376: -2.58 | M376: 55702.97 | N376: 3150.47 | O376: 0.06 | P376: -1643.65 | Q376: 20.03 | R376: 4.54 | S376: 0.23 | T376: 1.12 | U376: 60.28 | V376: 0.26 | W376: 0.0 | X376: -0.0 | Y376: 3.15 | Z376: 1886.9 | AA376: 29.52 | AB376: 0.03 | AC376: 4.41 | AD376: 6.69 | AF376: 50.02
A377: 424 | B377: Company_424 | C377: Finance | D377: Europe | E377: 17996.29 | F377: 2854.59 | G377: 0.16 | H377: 1793.8 | I377: 10.13 | J377: 0.63 | K377: 0.06 | L377: 0.19 | M377: 27593.97 | N377: 10722.34 | O377: 0.39 | P377: 5643.61 | Q377: 12.23 | R377: 5.25 | S377: 0.43 | T377: -2.23 | U377: 87.65 | V377: 0.54 | W377: 0.01 | X377: 0.19 | Y377: 1.53 | Z377: 1823.02 | AA377: 15.14 | AB377: 0.07 | AC377: 2.33 | AD377: 6.5 | AE377: 19.0 | AF377: 50.02
A378: 482 | B378: Company_482 | C378: Energy | D378: Europe | E378: 6194.51 | F378: 283.51 | G378: 0.05 | H378: 133.57 | I378: 11.77 | J378: 3.67 | K378: 0.31 | L378: 1.07 | M378: 10476.24 | N378: 2802.64 | O378: 0.27 | P378: 193.17 | Q378: 1.31 | R378: 6.09 | S378: 4.64 | T378: 0.83 | U378: 83.25 | V378: 1.75 | W378: 0.02 | X378: 1.01 | Y378: 1.69 | Z378: 729.09 | AA378: 14.37 | AB378: 0.07 | AC378: 0.22 | AD378: 66.8 | AE378: 50.5 | AF378: 50.02
A379: 521 | B379: Company_521 | C379: Technology | D379: Middle East | E379: 8135.07 | F379: 684.4 | G379: 0.08 | H379: 386.39 | I379: 21.15 | J379: 2.79 | K379: 0.13 | L379: -1.7 | M379: 38765.67 | N379: 9390.8 | O379: 0.24 | P379: -2608.37 | Q379: 6.07 | R379: 7.85 | S379: 1.29 | T379: -1.04 | U379: 72.89 | V379: 0.73 | W379: 0.01 | X379: 0.38 | Y379: 4.77 | Z379: 1720.57 | AA379: 22.53 | AB379: 0.04 | AC379: 0.77 | AD379: 29.14 | AE379: 38.0 | AF379: 50.02
A380: 149 | B380: Company_149 | C380: Technology | D380: Africa | E380: 19531.23 | F380: 4747.48 | G380: 0.24 | H380: 2979.05 | I380: 11.79 | J380: 2.33 | K380: 0.2 | L380: -1.18 | M380: 61280.21 | N380: 12156.05 | O380: 0.2 | P380: 6590.66 | Q380: 18.05 | R380: 5.48 | S380: 0.3 | T380: -1.13 | U380: 54.71 | V380: 2.01 | W380: 0.04 | X380: 1.21 | Y380: 3.14 | Z380: 2302.73 | AA380: 26.61 | AB380: 0.04 | AC380: 3.29 | AD380: 8.08 | AE380: 30.25 | AF380: 50.01
A381: 460 | B381: Company_460 | C381: Technology | D381: North America | E381: 4799.45 | F381: 768.23 | G381: 0.16 | H381: 474.22 | I381: 20.72 | J381: 2.05 | K381: 0.1 | L381: 0.75 | M381: 27435.87 | N381: 10224.07 | O381: 0.37 | P381: 5153.84 | Q381: 11.34 | R381: 6.98 | S381: 0.62 | T381: -2.37 | U381: 57.7 | V381: 1.0 | W381: 0.02 | X381: 0.54 | Y381: 5.72 | Z381: 994.45 | AA381: 27.59 | AB381: 0.04 | AC381: 1.62 | AD381: 16.98 | AE381: 27.0 | AF381: 50.01
A382: 800 | B382: Company_800 | C382: Transportation | D382: Asia | E382: 3098.22 | F382: 368.35 | G382: 0.12 | H382: 204.84 | I382: 15.13 | J382: 2.46 | K382: 0.16 | L382: 1.28 | M382: 7811.41 | N382: 2060.9 | O382: 0.26 | P382: 1094.89 | Q382: 6.24 | R382: 9.37 | S382: 1.5 | T382: -5.61 | U382: 43.77 | V382: 1.89 | W382: 0.04 | X382: 1.04 | Y382: 2.52 | Z382: 468.76 | AA382: 16.66 | AB382: 0.06 | AC382: 0.67 | AD382: 25.02 | AE382: 26.0 | AF382: 50.01
A383: 4 | B383: Company_4 | C383: Technology | D383: Africa | E383: 6065.22 | F383: 345.5 | G383: 0.06 | H383: 92.31 | I383: 26.91 | J383: 2.13 | K383: 0.08 | L383: -1.21 | M383: 39075.53 | N383: 4268.4 | O383: 0.11 | P383: 1095.8 | Q383: 3.27 | R383: 7.48 | S383: 2.29 | T383: 4.46 | U383: 61.85 | V383: 2.05 | W383: 0.03 | X383: 1.28 | Y383: 6.44 | Z383: 1632.15 | AA383: 23.94 | AB383: 0.04 | AC383: 0.44 | AD383: 54.76 | AE383: 42.67 | AF383: 50.0
A384: 12 | B384: Company_12 | C384: Finance | D384: Asia | E384: 3499.61 | F384: 159.61 | G384: 0.05 | H384: -69.13 | I384: 18.35 | J384: 2.01 | K384: 0.11 | L384: 0.61 | M384: 10860.24 | N384: 3117.58 | O384: 0.29 | P384: 1609.98 | Q384: -0.77 | R384: 5.82 | S384: -7.52 | T384: 1.78 | U384: 53.77 | V384: 1.3 | W384: 0.02 | X384: 0.8 | Y384: 3.1 | Z384: 642.18 | AA384: 16.91 | AB384: 0.06 | AC384: -0.13 | AD384: 178.16 | AE384: 40.0 | AF384: 50.0
A385: 32 | B385: Company_32 | C385: Utilities | D385: North America | E385: 491.15 | F385: 25.49 | G385: 0.05 | H385: 15.47 | I385: 6.93 | J385: 1.98 | K385: 0.29 | L385: 1.13 | M385: 323.2 | N385: 99.61 | O385: 0.31 | P385: 41.25 | Q385: 3.66 | R385: 2.83 | S385: 0.77 | T385: 1.26 | U385: 54.7 | V385: 0.74 | W385: 0.01 | X385: -0.33 | Y385: 0.66 | Z385: 34.04 | AA385: 9.5 | AB385: 0.11 | AC385: 1.29 | AD385: 7.34 | AE385: -33.0 | AF385: 50.0
A386: 34 | B386: Company_34 | C386: Energy | D386: Middle East | E386: 14445.64 | F386: 2775.88 | G386: 0.19 | H386: 1580.76 | I386: 17.96 | J386: 2.31 | K386: 0.13 | L386: 0.03 | M386: 30725.83 | N386: 10196.26 | O386: 0.33 | P386: 3141.28 | Q386: 15.69 | R386: 12.42 | S386: 0.79 | T386: 6.28 | U386: 35.37 | V386: 0.3 | W386: 0.01 | X386: 0.14 | Y386: 2.13 | Z386: 2594.44 | AA386: 11.84 | AB386: 0.08 | AC386: 1.26 | AD386: 9.37 | AE386: 14.0 | AF386: 50.0
A387: 66 | B387: Company_66 | C387: Consumer Goods | D387: Middle East | E387: 1885.07 | F387: 178.09 | G387: 0.09 | H387: 110.32 | I387: 25.61 | J387: 1.31 | K387: 0.05 | L387: -0.5 | M387: 6239.35 | N387: 1925.11 | O387: 0.31 | P387: -974.9 | Q387: 5.52 | R387: 3.25 | S387: 0.59 | T387: -1.02 | U387: 61.74 | V387: 1.02 | W387: 0.02 | X387: 0.33 | Y387: 3.31 | Z387: 482.77 | AA387: 12.92 | AB387: 0.08 | AC387: 1.7 | AD387: 7.61 | AE387: 16.5 | AF387: 50.0
...

Sheet scored_27_rules
A1: CompanyID | B1: CompanyName | C1: Industry | D1: Region | E1: Revenue_WMA | F1: Revenue_std | G1: Revenue_cv | H1: Revenue_slope | I1: ProfitMargin_WMA | J1: ProfitMargin_std | K1: ProfitMargin_cv | L1: ProfitMargin_slope | M1: MarketCap_WMA | N1: MarketCap_std | O1: MarketCap_cv | P1: MarketCap_slope | Q1: GrowthRate_WMA | R1: GrowthRate_std | S1: GrowthRate_cv | T1: GrowthRate_slope | U1: ESG_Overall_WMA | V1: ESG_Overall_std | W1: ESG_Overall_cv | X1: ESG_Overall_slope | Y1: PriceToSales | Z1: NetIncome | AA1: PriceToEarnings | AB1: EarningsYield | AC1: Risk-AdjustedGrowth | AD1: Earnings-to-Growth | AE1: ESG_Signal-to-Noise | AF1: TARGET_SCORE
A2: 918 | B2: Company_918 | C2: Utilities | D2: Asia | E2: 1568.43 | F2: 202.29 | G2: 0.13 | H2: 127.21 | I2: 7.63 | J2: 0.27 | K2: 0.04 | L2: 0.11 | M2: 1275.9 | N2: 203.69 | O2: 0.16 | P2: 42.27 | Q2: 8.46 | R2: 2.77 | S2: 0.33 | T2: -1.23 | U2: 58.63 | V2: 1.06 | W2: 0.02 | X2: 0.58 | Y2: 0.81 | Z2: 119.67 | AA2: 10.66 | AB2: 0.09 | AC2: 3.05 | AD2: 3.49 | AE2: 29.0 | AF2: 80.44
A3: 467 | B3: Company_467 | C3: Manufacturing | D3: Middle East | E3: 1108.43 | F3: 186.43 | G3: 0.17 | H3: 117.05 | I3: 9.51 | J3: 1.92 | K3: 0.2 | L3: 0.52 | M3: 1666.81 | N3: 629.88 | O3: 0.38 | P3: 363.52 | Q3: 12.49 | R3: 3.73 | S3: 0.3 | T3: -0.61 | U3: 41.35 | V3: 0.61 | W3: 0.01 | X3: 0.29 | Y3: 1.5 | Z3: 105.41 | AA3: 15.81 | AB3: 0.06 | AC3: 3.35 | AD3: 4.72 | AE3: 29.0 | AF3: 80.43
A4: 723 | B4: Company_723 | C4: Manufacturing | D4: Asia | E4: 11292.97 | F4: 2137.37 | G4: 0.19 | H4: 1332.47 | I4: 15.54 | J4: 1.82 | K4: 0.12 | L4: -0.75 | M4: 31411.33 | N4: 8907.51 | O4: 0.28 | P4: 3808.9 | Q4: 14.61 | R4: 4.4 | S4: 0.3 | T4: -0.05 | U4: 75.04 | V4: 1.21 | W4: 0.02 | X4: 0.42 | Y4: 2.78 | Z4: 1754.93 | AA4: 17.9 | AB4: 0.06 | AC4: 3.32 | AD4: 5.39 | AE4: 21.0 | AF4: 80.29
A5: 910 | B5: Company_910 | C5: Finance | D5: Oceania | E5: 2880.71 | F5: 346.15 | G5: 0.12 | H5: 217.87 | I5: 17.7 | J5: 2.83 | K5: 0.16 | L5: -1.38 | M5: 7310.89 | N5: 1726.57 | O5: 0.24 | P5: 345.01 | Q5: 7.97 | R5: 2.6 | S5: 0.33 | T5: -1.01 | U5: 75.54 | V5: 0.83 | W5: 0.01 | X5: 0.45 | Y5: 2.54 | Z5: 509.89 | AA5: 14.34 | AB5: 0.07 | AC5: 3.07 | AD5: 4.68 | AE5: 45.0 | AF5: 80.21
A6: 503 | B6: Company_503 | C6: Manufacturing | D6: North America | E6: 5753.15 | F6: 992.39 | G6: 0.17 | H6: 617.51 | I6: 16.64 | J6: 0.69 | K6: 0.04 | L6: 0.06 | M6: 14527.13 | N6: 5183.06 | O6: 0.36 | P6: 2499.46 | Q6: 13.45 | R6: 3.98 | S6: 0.3 | T6: -0.1 | U6: 53.25 | V6: 0.63 | W6: 0.01 | X6: 0.34 | Y6: 2.53 | Z6: 957.32 | AA6: 15.17 | AB6: 0.07 | AC6: 3.38 | AD6: 4.49 | AE6: 34.0 | AF6: 80.21
A7: 430 | B7: Company_430 | C7: Healthcare | D7: Oceania | E7: 14805.67 | F7: 3381.08 | G7: 0.23 | H7: 2133.65 | I7: 6.87 | J7: 1.55 | K7: 0.23 | L7: -0.44 | M7: 19152.49 | N7: 4747.46 | O7: 0.25 | P7: 851.11 | Q7: 16.35 | R7: 4.63 | S7: 0.28 | T7: 0.38 | U7: 74.26 | V7: 0.73 | W7: 0.01 | X7: 0.45 | Y7: 1.29 | Z7: 1017.15 | AA7: 18.83 | AB7: 0.05 | AC7: 3.53 | AD7: 5.33 | AE7: 45.0 | AF7: 80.21
A8: 258 | B8: Company_258 | C8: Healthcare | D8: Latin America | E8: 6821.16 | F8: 1450.97 | G8: 0.21 | H8: 899.31 | I8: 14.42 | J8: 2.0 | K8: 0.14 | L8: 0.63 | M8: 14239.57 | N8: 4303.17 | O8: 0.3 | P8: 1186.33 | Q8: 17.11 | R8: 5.44 | S8: 0.32 | T8: 1.06 | U8: 55.59 | V8: 2.01 | W8: 0.04 | X8: 1.09 | Y8: 2.09 | Z8: 983.61 | AA8: 14.48 | AB8: 0.07 | AC8: 3.15 | AD8: 4.6 | AE8: 27.25 | AF8: 80.21
A9: 69 | B9: Company_69 | C9: Energy | D9: North America | E9: 9226.73 | F9: 1121.8 | G9: 0.12 | H9: 694.19 | I9: 26.98 | J9: 4.62 | K9: 0.17 | L9: 2.46 | M9: 34591.53 | N9: 9476.64 | O9: 0.27 | P9: 4142.65 | Q9: 8.67 | R9: 2.97 | S9: 0.34 | T9: 1.61 | U9: 49.61 | V9: 2.75 | W9: 0.06 | X9: 1.69 | Y9: 3.75 | Z9: 2489.37 | AA9: 13.9 | AB9: 0.07 | AC9: 2.92 | AD9: 4.76 | AE9: 28.17 | AF9: 80.21
A10: 27 | B10: Company_27 | C10: Healthcare | D10: Europe | E10: 4265.04 | F10: 955.53 | G10: 0.22 | H10: 595.17 | I10: 9.86 | J10: 2.74 | K10: 0.28 | L10: 1.59 | M10: 7374.9 | N10: 3096.58 | O10: 0.42 | P10: 1708.5 | Q10: 17.96 | R10: 4.11 | S10: 0.23 | T10: 0.81 | U10: 65.21 | V10: 0.79 | W10: 0.01 | X10: 0.44 | Y10: 1.73 | Z10: 420.53 | AA10: 17.54 | AB10: 0.06 | AC10: 4.37 | AD10: 4.01 | AE10: 44.0 | AF10: 80.21
A11: 62 | B11: Company_62 | C11: Technology | D11: Asia | E11: 7936.37 | F11: 1559.57 | G11: 0.2 | H11: 985.72 | I11: 26.96 | J11: 1.62 | K11: 0.06 | L11: 0.57 | M11: 45275.47 | N11: 11475.22 | O11: 0.25 | P11: 6529.46 | Q11: 14.17 | R11: 3.08 | S11: 0.22 | T11: -1.67 | U11: 61.28 | V11: 0.67 | W11: 0.01 | X11: 0.33 | Y11: 5.7 | Z11: 2139.65 | AA11: 21.16 | AB11: 0.05 | AC11: 4.6 | AD11: 4.6 | AE11: 33.0 | AF11: 80.2
A12: 411 | B12: Company_411 | C12: Healthcare | D12: Africa | E12: 7396.73 | F12: 2069.45 | G12: 0.28 | H12: 1297.87 | I12: 15.83 | J12: 3.14 | K12: 0.2 | L12: 1.54 | M12: 24597.97 | N12: 14423.55 | O12: 0.59 | P12: 8391.47 | Q12: 22.4 | R12: 4.87 | S12: 0.22 | T12: 1.41 | U12: 60.27 | V12: 1.08 | W12: 0.02 | X12: 0.65 | Y12: 3.33 | Z12: 1170.9 | AA12: 21.01 | AB12: 0.05 | AC12: 4.6 | AD12: 4.57 | AE12: 32.5 | AF12: 80.19
A13: 434 | B13: Company_434 | C13: Transportation | D13: Latin America | E13: 844.54 | F13: 181.86 | G13: 0.22 | H13: 112.71 | I13: 5.71 | J13: 2.17 | K13: 0.38 | L13: -1.0 | M13: 727.55 | N13: 349.64 | O13: 0.48 | P13: -40.94 | Q13: 16.95 | R13: 4.7 | S13: 0.28 | T13: 2.14 | U13: 54.99 | V13: 2.3 | W13: 0.04 | X13: 1.37 | Y13: 0.86 | Z13: 48.22 | AA13: 15.09 | AB13: 0.07 | AC13: 3.61 | AD13: 4.18 | AE13: 34.25 | AF13: 80.18
... A304: 591 | B304: Company_591 | C304: Manufacturing | D304: Oceania | E304: 1668.06 | F304: 295.59 | G304: 0.18 | H304: 185.28 | I304: -1.29 | J304: 0.42 | K304: -0.33 | L304: 0.19 | M304: 4754.21 | N304: 2914.18 | O304: 0.61 | P304: 1055.93 | Q304: 12.99 | R304: 3.7 | S304: 0.29 | T304: 0.73 | U304: 63.79 | V304: 1.3 | W304: 0.02 | X304: 0.79 | Y304: 2.85 | Z304: -21.52 | AA304: -220.94 | AB304: -0.0 | AC304: 3.51 | AD304: 178.16 | AE304: 39.5 | AF304: 64.04
A305: 36 | B305: Company_36 | C305: Healthcare | D305: Europe | E305: 2642.85 | F305: 284.14 | G305: 0.11 | H305: 172.99 | I305: 27.65 | J305: 1.82 | K305: 0.07 | L305: 0.74 | M305: 13914.46 | N305: 3438.9 | O305: 0.25 | P305: 1801.59 | Q305: 7.47 | R305: 5.27 | S305: 0.7 | T305: 0.14 | U305: 76.24 | V305: 0.26 | W305: 0.0 | X305: -0.0 | Y305: 5.26 | Z305: 730.75 | AA305: 19.04 | AB305: 0.05 | AC305: 1.42 | AD305: 13.43 | AF305: 64.0
A306: 720 | B306: Company_720 | C306: Energy | D306: Asia | E306: 11910.21 | F306: 1276.2 | G306: 0.11 | H306: 791.86 | I306: 15.21 | J306: 2.78 | K306: 0.18 | L306: 1.43 | M306: 25070.95 | N306: 6604.58 | O306: 0.26 | P306: 2812.16 | Q306: 6.81 | R306: 4.17 | S306: 0.61 | T306: -0.07 | U306: 57.68 | V306: 1.67 | W306: 0.03 | X306: 1.05 | Y306: 2.1 | Z306: 1811.54 | AA306: 13.84 | AB306: 0.07 | AC306: 1.63 | AD306: 8.47 | AE306: 35.0 | AF306: 63.95
A307: 255 | B307: Company_255 | C307: Consumer Goods | D307: Oceania | E307: 3046.18 | F307: 263.55 | G307: 0.09 | H307: 149.58 | I307: 4.8 | J307: 1.78 | K307: 0.37 | L307: -0.63 | M307: 2433.14 | N307: 1379.65 | O307: 0.57 | P307: -379.5 | Q307: 6.05 | R307: 7.83 | S307: 1.29 | T307: -3.73 | U307: 64.87 | V307: 1.86 | W307: 0.03 | X307: 1.15 | Y307: 0.8 | Z307: 146.22 | AA307: 16.64 | AB307: 0.06 | AC307: 0.77 | AD307: 21.54 | AE307: 38.33 | AF307: 63.93
A308: 627 | B308: Company_627 | C308: Transportation | D308: Africa | E308: 721.75 | F308: 72.7 | G308: 0.1 | H308: 43.67 | I308: 11.19 | J308: 1.41 | K308: 0.13 | L308: -0.13 | M308: 1121.39 | N308: 391.07 | O308: 0.35 | P308: -114.19 | Q308: 7.67 | R308: 4.56 | S308: 0.59 | T308: 2.05 | U308: 46.75 | V308: 1.37 | W308: 0.03 | X308: 0.82 | Y308: 1.55 | Z308: 80.76 | AA308: 13.88 | AB308: 0.07 | AC308: 1.68 | AD308: 8.25 | AE308: 27.33 | AF308: 63.9
A309: 448 | B309: Company_448 | C309: Finance | D309: Middle East | E309: 10452.82 | F309: 2059.11 | G309: 0.2 | H309: 1284.21 | I309: 11.4 | J309: 2.63 | K309: 0.23 | L309: -0.75 | M309: 15797.84 | N309: 6889.06 | O309: 0.44 | P309: 1617.93 | Q309: 12.9 | R309: 7.62 | S309: 0.59 | T309: -1.77 | U309: 54.37 | V309: 1.61 | W309: 0.03 | X309: 0.97 | Y309: 1.51 | Z309: 1191.62 | AA309: 13.26 | AB309: 0.08 | AC309: 1.69 | AD309: 7.83 | AE309: 32.33 | AF309: 63.9
A310: 143 | B310: Company_143 | C310: Consumer Goods | D310: Oceania | E310: 1346.29 | F310: 81.74 | G310: 0.06 | H310: 10.09 | I310: 17.07 | J310: 1.1 | K310: 0.06 | L310: -0.26 | M310: 4611.03 | N310: 871.31 | O310: 0.19 | P310: 27.02 | Q310: -1.21 | R310: 10.77 | S310: -8.92 | T310: 1.1 | U310: 72.48 | V310: 2.8 | W310: 0.04 | X310: 1.68 | Y310: 3.42 | Z310: 229.81 | AA310: 20.06 | AB310: 0.05 | AC310: -0.11 | AD310: 178.16 | AE310: 42.0 | AF310: 63.87
A311: 814 | B311: Company_814 | C311: Consumer Goods | D311: Latin America | E311: 1342.61 | F311: 223.39 | G311: 0.17 | H311: 140.39 | I311: 13.93 | J311: 1.69 | K311: 0.12 | L311: 0.85 | M311: 3401.05 | N311: 1474.33 | O311: 0.43 | P311: 579.67 | Q311: 11.11 | R311: 6.56 | S311: 0.59 | T311: 3.38 | U311: 64.87 | V311: 1.54 | W311: 0.02 | X311: 0.83 | Y311: 2.53 | Z311: 187.03 | AA311: 18.18 | AB311: 0.05 | AC311: 1.69 | AD311: 10.74 | AE311: 41.5 | AF311: 63.85
A312: 506 | B312: Company_506 | C312: Retail | D312: North America | E312: 9287.27 | F312: 1183.84 | G312: 0.13 | H312: 718.43 | I312: 16.86 | J312: 2.81 | K312: 0.17 | L312: 1.65 | M312: 27280.89 | N312: 9414.96 | O312: 0.35 | P312: 5157.88 | Q312: 8.65 | R312: 6.57 | S312: 0.76 | T312: -1.9 | U312: 65.63 | V312: 3.02 | W312: 0.05 | X312: 1.91 | Y312: 2.94 | Z312: 1565.83 | AA312: 17.42 | AB312: 0.06 | AC312: 1.32 | AD312: 13.23 | AE312: 38.2 | AF312: 63.85
A313: 17 | B313: Company_17 | C313: Utilities | D313: Oceania | E313: 4051.09 | F313: 150.42 | G313: 0.04 | H313: -71.59 | I313: 16.24 | J313: 0.88 | K313: 0.05 | L313: -0.42 | M313: 6751.02 | N313: 2098.82 | O313: 0.31 | P313: -1208.94 | Q313: -0.61 | R313: 5.32 | S313: -8.67 | T313: -1.04 | U313: 67.52 | V313: 0.62 | W313: 0.01 | X313: 0.24 | Y313: 1.67 | Z313: 657.9 | AA313: 10.26 | AB313: 0.1 | AC313: -0.11 | AD313: 178.16 | AE313: 24.0 | AF313: 63.84
A314: 263 | B314: Company_263 | C314: Utilities | D314: Africa | E314: 1517.48 | F314: 49.5 | G314: 0.03 | H314: -12.81 | I314: 14.47 | J314: 2.11 | K314: 0.15 | L314: 1.3 | M314: 2324.31 | N314: 354.01 | O314: 0.15 | P314: 3.83 | Q314: -0.51 | R314: 5.58 | S314: -10.87 | T314: 1.09 | U314: 33.65 | V314: 0.63 | W314: 0.02 | X314: 0.35 | Y314: 1.53 | Z314: 219.58 | AA314: 10.59 | AB314: 0.09 | AC314: -0.09 | AD314: 178.16 | AE314: 17.5 | AF314: 63.81
A315: 34 | B315: Company_34 | C315: Energy | D315: Middle East | E315: 14445.64 | F315: 2775.88 | G315: 0.19 | H315: 1580.76 | I315: 17.96 | J315: 2.31 | K315: 0.13 | L315: 0.03 | M315: 30725.83 | N315: 10196.26 | O315: 0.33 | P315: 3141.28 | Q315: 15.69 | R315: 12.42 | S315: 0.79 | T315: 6.28 | U315: 35.37 | V315: 0.3 | W315: 0.01 | X315: 0.14 | Y315: 2.13 | Z315: 2594.44 | AA315: 11.84 | AB315: 0.08 | AC315: 1.26 | AD315: 9.37 | AE315: 14.0 | AF315: 63.76
A316: 665 | B316: Company_665 | C316: Technology | D316: Asia | E316: 10015.1 | F316: 1735.01 | G316: 0.17 | H316: 1086.36 | I316: 16.8 | J316: 1.54 | K316: 0.09 | L316: -0.33 | M316: 41189.97 | N316: 7805.13 | O316: 0.19 | P316: -68.75 | Q316: 11.35 | R316: 10.6 | S316: 0.93 | T316: 4.99 | U316: 60.61 | V316: 1.93 | W316: 0.03 | X316: 1.19 | Y316: 4.11 | Z316: 1682.54 | AA316: 24.48 | AB316: 0.04 | AC316: 1.07 | AD316: 22.86 | AE316: 39.67 | AF316: 63.75
A317: 521 | B317: Company_521 | C317: Technology | D317: Middle East | E317: 8135.07 | F317: 684.4 | G317: 0.08 | H317: 386.39 | I317: 21.15 | J317: 2.79 | K317: 0.13 | L317: -1.7 | M317: 38765.67 | N317: 9390.8 | O317: 0.24 | P317: -2608.37 | Q317: 6.07 | R317: 7.85 | S317: 1.29 | T317: -1.04 | U317: 72.89 | V317: 0.73 | W317: 0.01 | X317: 0.38 | Y317: 4.77 | Z317: 1720.57 | AA317: 22.53 | AB317: 0.04 | AC317: 0.77 | AD317: 29.14 | AE317: 38.0 | AF317: 63.75
... A503: 376 | B503: Company_376 | C503: Technology | D503: Oceania | E503: 1694.06 | F503: 118.75 | G503: 0.07 | H503: 66.39 | I503: 12.74 | J503: 1.91 | K503: 0.15 | L503: -0.81 | M503: 6340.27 | N503: 874.58 | O503: 0.14 | P503: 344.81 | Q503: 2.38 | R503: 5.03 | S503: 2.11 | T503: -0.54 | U503: 89.95 | V503: 1.84 | W503: 0.02 | X503: 0.95 | Y503: 3.74 | Z503: 215.82 | AA503: 29.38 | AB503: 0.03 | AC503: 0.47 | AD503: 62.09 | AE503: 47.5 | AF503: 60.51
A504: 291 | B504: Company_291 | C504: Technology | D504: Oceania | E504: 17700.79 | F504: 4699.75 | G504: 0.27 | H504: 2957.35 | I504: 10.66 | J504: 4.08 | K504: 0.38 | L504: -2.58 | M504: 55702.97 | N504: 3150.47 | O504: 0.06 | P504: -1643.65 | Q504: 20.03 | R504: 4.54 | S504: 0.23 | T504: 1.12 | U504: 60.28 | V504: 0.26 | W504: 0.0 | X504: -0.0 | Y504: 3.15 | Z504: 1886.9 | AA504: 29.52 | AB504: 0.03 | AC504: 4.41 | AD504: 6.69 | AF504: 60.51
A505: 152 | B505: Company_152 | C505: Technology | D505: Latin America | E505: 24933.79 | F505: 1186.08 | G505: 0.05 | H505: -342.5 | I505: 30.91 | J505: 2.46 | K505: 0.08 | L505: 1.51 | M505: 223906.92 | N505: 31982.89 | O505: 0.14 | P505: 14978.25 | Q505: -2.83 | R505: 6.47 | S505: -2.28 | T505: -0.2 | U505: 65.87 | V505: 0.98 | W505: 0.01 | X505: 0.59 | Y505: 8.98 | Z505: 7707.03 | AA505: 29.05 | AB505: 0.03 | AC505: -0.44 | AD505: 178.16 | AE505: 59.0 | AF505: 60.51
A506: 126 | B506: Company_126 | C506: Manufacturing | D506: Oceania | E506: 3487.52 | F506: 336.6 | G506: 0.1 | H506: 201.66 | I506: 3.81 | J506: 2.99 | K506: 0.79 | L506: 0.76 | M506: 5139.27 | N506: 4961.38 | O506: 0.97 | P506: 973.45 | Q506: 6.66 | R506: 6.67 | S506: 1.0 | T506: 1.23 | U506: 44.76 | V506: 1.51 | W506: 0.03 | X506: 0.93 | Y506: 1.47 | Z506: 132.87 | AA506: 38.68 | AB506: 0.03 | AC506: 1.0 | AD506: 38.74 | AE506: 31.0 | AF506: 60.51
A507: 24 | B507: Company_24 | C507: Technology | D507: Middle East | E507: 15439.7 | F507: 1110.44 | G507: 0.07 | H507: 638.28 | I507: 23.36 | J507: 3.89 | K507: 0.17 | L507: 2.22 | M507: 104067.45 | N507: 36139.06 | O507: 0.35 | P507: 21129.05 | Q507: 5.39 | R507: 5.14 | S507: 0.95 | T507: 0.37 | U507: 56.07 | V507: 1.65 | W507: 0.03 | X507: 0.92 | Y507: 6.74 | Z507: 3606.71 | AA507: 28.85 | AB507: 0.03 | AC507: 1.05 | AD507: 27.52 | AE507: 30.67 | AF507: 60.51
A508: 617 | B508: Company_617 | C508: Healthcare | D508: Asia | E508: 7431.93 | F508: 1377.45 | G508: 0.19 | H508: 867.91 | I508: -4.71 | J508: 3.74 | K508: -0.79 | L508: -2.08 | M508: 23401.11 | N508: 11377.94 | O508: 0.49 | P508: 5988.43 | Q508: 14.88 | R508: 7.13 | S508: 0.48 | T508: -3.39 | U508: 62.53 | V508: 1.71 | W508: 0.03 | X508: 0.97 | Y508: 3.15 | Z508: -350.04 | AA508: -66.85 | AB508: -0.01 | AC508: 2.09 | AD508: 178.16 | AE508: 32.33 | AF508: 60.5
A509: 799 | B509: Company_799 | C509: Consumer Goods | D509: Oceania | E509: 4354.55 | F509: 371.0 | G509: 0.09 | H509: 229.39 | I509: 1.46 | J509: 2.98 | K509: 2.04 | L509: -1.26 | M509: 1830.51 | N509: 1930.56 | O509: 1.05 | P509: -1073.05 | Q509: 5.54 | R509: 4.59 | S509: 0.83 | T509: -1.77 | U509: 74.28 | V509: 0.8 | W509: 0.01 | X509: 0.3 | Y509: 0.42 | Z509: 63.58 | AA509: 28.79 | AB509: 0.03 | AC509: 1.21 | AD509: 23.85 | AE509: 30.0 | AF509: 60.49
A510: 555 | B510: Company_555 | C510: Energy | D510: Africa | E510: 2519.62 | F510: 160.63 | G510: 0.06 | H510: -56.4 | I510: 24.39 | J510: 3.67 | K510: 0.15 | L510: 1.69 | M510: 8810.9 | N510: 2877.97 | O510: 0.33 | P510: 399.45 | Q510: -2.57 | R510: 7.18 | S510: -2.8 | T510: -3.61 | U510: 38.93 | V510: 3.55 | W510: 0.09 | X510: 2.23 | Y510: 3.5 | Z510: 614.54 | AA510: 14.34 | AB510: 0.07 | AC510: -0.36 | AD510: 178.16 | AE510: 24.78 | AF510: 60.49
A511: 393 | B511: Company_393 | C511: Transportation | D511: North America | E511: 939.77 | F511: 177.56 | G511: 0.19 | H511: 108.97 | I511: 1.34 | J511: 2.98 | K511: 2.22 | L511: 1.32 | M511: 896.42 | N511: 1307.57 | O511: 1.46 | P511: -138.12 | Q511: 13.12 | R511: 8.68 | S511: 0.66 | T511: 0.09 | U511: 79.68 | V511: 0.69 | W511: 0.01 | X511: 0.36 | Y511: 0.95 | Z511: 12.59 | AA511: 71.18 | AB511: 0.01 | AC511: 1.51 | AD511: 47.09 | AE511: 36.0 | AF511: 60.48
A512: 182 | B512: Company_182 | C512: Manufacturing | D512: North America | E512: 3174.91 | F512: 150.9 | G512: 0.05 | H512: 9.8 | I512: 7.83 | J512: 2.54 | K512: 0.32 | L512: 1.58 | M512: 4069.0 | N512: 1543.27 | O512: 0.38 | P512: 829.86 | Q512: 0.15 | R512: 8.9 | S512: 60.68 | T512: 0.37 | U512: 68.47 | V512: 1.15 | W512: 0.02 | X512: 0.65 | Y512: 1.28 | Z512: 248.6 | AA512: 16.37 | AB512: 0.06 | AC512: 0.02 | AD512: 971.17 | AE512: 32.5 | AF512: 60.45
A513: 753 | B513: Company_753 | C513: Healthcare | D513: Europe | E513: 1339.82 | F513: 66.48 | G513: 0.05 | H513: -9.84 | I513: 30.55 | J513: 6.01 | K513: 0.2 | L513: 3.64 | M513: 6987.07 | N513: 2353.77 | O513: 0.34 | P513: 270.41 | Q513: -2.53 | R513: 6.81 | S513: -2.69 | T513: -2.62 | U513: 81.07 | V513: 1.47 | W513: 0.02 | X513: 0.92 | Y513: 5.21 | Z513: 409.32 | AA513: 17.07 | AB513: 0.06 | AC513: -0.37 | AD513: 178.16 | AE513: 46.0 | AF513: 60.42
A514: 336 | B514: Company_336 | C514: Retail | D514: North America | E514: 2601.28 | F514: 97.23 | G514: 0.04 | H514: -49.29 | I514: 9.51 | J514: 0.84 | K514: 0.09 | L514: 0.08 | M514: 3615.43 | N514: 1428.8 | O514: 0.4 | P514: -875.63 | Q514: -1.67 | R514: 4.53 | S514: -2.71 | T514: -0.95 | U514: 63.41 | V514: 1.65 | W514: 0.03 | X514: 0.88 | Y514: 1.39 | Z514: 247.38 | AA514: 14.61 | AB514: 0.07 | AC514: -0.37 | AD514: 178.16 | AE514: 29.33 | AF514: 60.41
A515: 19 | B515: Company_19 | C515: Technology | D515: Latin America | E515: 137774.04 | F515: 21661.99 | G515: 0.16 | H515: 13424.76 | I515: 3.93 | J515: 2.26 | K515: 0.58 | L515: -1.19 | M515: 135850.51 | N515: 71227.63 | O515: 0.52 | P515: -29698.7 | Q515: 10.65 | R515: 8.62 | S515: 0.81 | T515: -0.55 | U515: 54.8 | V515: 1.68 | W515: 0.03 | X515: 0.96 | Y515: 0.99 | Z515: 5414.52 | AA515: 25.09 | AB515: 0.04 | AC515: 1.24 | AD515: 20.31 | AE515: 32.0 | AF515: 60.32
...

Sheet Comparisson
A1: Scored Company data top10 | E1: scored_27_results - comparisson | K1: Scored_27_results top10 | O1: Scored Company data - comparisson
A2: CompanyID | B2: Target Score | C2: placement | E2: CompanyID | F2: Target Score | G2: placement | K2: CompanyID | L2: Target Score | M2: placement | O2: CompanyID | P2: Target Score | Q2: placement
A3: 614 | B3: =_xlfn.XLOOKUP(A3, scored_company_data!A:A, scored_company_data!AF:AF, "Brak firmy") -> 86.87 | C3: 1 | E3: =A3 -> 614 | F3: =_xlfn.XLOOKUP(A3, scored_27_rules!A:A, scored_27_rules!AF:AF, "Brak firmy") -> 72.78 | G3: =MATCH(E3, scored_27_rules!A:A, 0) - 1 -> 73 | K3: 918 | L3: =_xlfn.XLOOKUP(K3, scored_27_rules!A:A, scored_27_rules!AF:AF, "Brak firmy") -> 80.44 | M3: 1 | O3: 918 | P3: =_xlfn.XLOOKUP(O3, scored_company_data!A:A, scored_company_data!AF:AF, "Brak firmy") -> 62.14 | Q3: =MATCH(O3, scored_company_data!A:A, 0) - 1 -> 147
A4: 270 | B4: =_xlfn.XLOOKUP(A4, scored_company_data!A:A, scored_company_data!AF:AF, "Brak firmy") -> 86.77 | C4: 2 | E4: =A4 -> 270 | F4: =_xlfn.XLOOKUP(A4, scored_27_rules!A:A, scored_27_rules!AF:AF, "Brak firmy") -> 70.02 | G4: =MATCH(E4, scored_27_rules!A:A, 0) - 1 -> 122 | K4: 467 | L4: =_xlfn.XLOOKUP(K4, scored_27_rules!A:A, scored_27_rules!AF:AF, "Brak firmy") -> 80.43 | M4: 2 | O4: 467 | P4: =_xlfn.XLOOKUP(O4, scored_company_data!A:A, scored_company_data!AF:AF, "Brak firmy") -> 58.95 | Q4: =MATCH(O4, scored_company_data!A:A, 0) - 1 -> 210
A5: 580 | B5: =_xlfn.XLOOKUP(A5, scored_company_data!A:A, scored_company_data!AF:AF, "Brak firmy") -> 85.72 | C5: 3 | E5: =A5 -> 580 | F5: =_xlfn.XLOOKUP(A5, scored_27_rules!A:A, scored_27_rules!AF:AF, "Brak firmy") -> 69.3 | G5: =MATCH(E5, scored_27_rules!A:A, 0) - 1 -> 139 | K5: 723 | L5: =_xlfn.XLOOKUP(K5, scored_27_rules!A:A, scored_27_rules!AF:AF, "Brak firmy") -> 80.29 | M5: 3 | O5: 723 | P5: =_xlfn.XLOOKUP(O5, scored_company_data!A:A, scored_company_data!AF:AF, "Brak firmy") -> 54.7 | Q5: =MATCH(O5, scored_company_data!A:A, 0) - 1 -> 297
A6: 746 | B6: =_xlfn.XLOOKUP(A6, scored_company_data!A:A, scored_company_data!AF:AF, "Brak firmy") -> 83.62 | C6: 4 | E6: =A6 -> 746 | F6: =_xlfn.XLOOKUP(A6, scored_27_rules!A:A, scored_27_rules!AF:AF, "Brak firmy") -> 71.36 | G6: =MATCH(E6, scored_27_rules!A:A, 0) - 1 -> 85 | K6: 910 | L6: =_xlfn.XLOOKUP(K6, scored_27_rules!A:A, scored_27_rules!AF:AF, "Brak firmy") -> 80.21 | M6: 4 | O6: 910 | P6: =_xlfn.XLOOKUP(O6, scored_company_data!A:A, scored_company_data!AF:AF, "Brak firmy") -> 74.35 | Q6: =MATCH(O6, scored_company_data!A:A, 0) - 1 -> 23
A7: 39 | B7: =_xlfn.XLOOKUP(A7, scored_company_data!A:A, scored_company_data!AF:AF, "Brak firmy") -> 82.6 | C7: 5 | E7: =A7 -> 39 | F7: =_xlfn.XLOOKUP(A7, scored_27_rules!A:A, scored_27_rules!AF:AF, "Brak firmy") -> 79.88 | G7: =MATCH(E7, scored_27_rules!A:A, 0) - 1 -> 16 | K7: 503 | L7: =_xlfn.XLOOKUP(K7, scored_27_rules!A:A, scored_27_rules!AF:AF, "Brak firmy") -> 80.21 | M7: 5 | O7: 503 | P7: =_xlfn.XLOOKUP(O7, scored_company_data!A:A, scored_company_data!AF:AF, "Brak firmy") -> 63.56 | Q7: =MATCH(O7, scored_company_data!A:A, 0) - 1 -> 120
A8: 626 | B8: =_xlfn.XLOOKUP(A8, scored_company_data!A:A, scored_company_data!AF:AF, "Brak firmy") -> 82.21 | C8: 6 | E8: =A8 -> 626 | F8: =_xlfn.XLOOKUP(A8, scored_27_rules!A:A, scored_27_rules!AF:AF, "Brak firmy") -> 67.44 | G8: =MATCH(E8, scored_27_rules!A:A, 0) - 1 -> 174 | K8: 430 | L8: =_xlfn.XLOOKUP(K8, scored_27_rules!A:A, scored_27_rules!AF:AF, "Brak firmy") -> 80.21 | M8: 6 | O8: 430 | P8: =_xlfn.XLOOKUP(O8, scored_company_data!A:A, scored_company_data!AF:AF, "Brak firmy") -> 74.32 | Q8: =MATCH(O8, scored_company_data!A:A, 0) - 1 -> 24
A9: 335 | B9: =_xlfn.XLOOKUP(A9, scored_company_data!A:A, scored_company_data!AF:AF, "Brak firmy") -> 82.07 | C9: 7 | E9: =A9 -> 335 | F9: =_xlfn.XLOOKUP(A9, scored_27_rules!A:A, scored_27_rules!AF:AF, "Brak firmy") -> 72.19 | G9: =MATCH(E9, scored_27_rules!A:A, 0) - 1 -> 79 | K9: 258 | L9: =_xlfn.XLOOKUP(K9, scored_27_rules!A:A, scored_27_rules!AF:AF, "Brak firmy") -> 80.21 | M9: 7 | O9: 258 | P9: =_xlfn.XLOOKUP(O9, scored_company_data!A:A, scored_company_data!AF:AF, "Brak firmy") -> 62.14 | Q9: =MATCH(O9, scored_company_data!A:A, 0) - 1 -> 146
A10: 838 | B10: =_xlfn.XLOOKUP(A10, scored_company_data!A:A, scored_company_data!AF:AF, "Brak firmy") -> 81.99 | C10: 8 | E10: =A10 -> 838 | F10: =_xlfn.XLOOKUP(A10, scored_27_rules!A:A, scored_27_rules!AF:AF, "Brak firmy") -> 67.65 | G10: =MATCH(E10, scored_27_rules!A:A, 0) - 1 -> 169 | K10: 69 | L10: =_xlfn.XLOOKUP(K10, scored_27_rules!A:A, scored_27_rules!AF:AF, "Brak firmy") -> 80.21 | M10: 8 | O10: 69 | P10: =_xlfn.XLOOKUP(O10, scored_company_data!A:A, scored_company_data!AF:AF, "Brak firmy") -> 53.56 | Q10: =MATCH(O10, scored_company_data!A:A, 0) - 1 -> 312
A11: 840 | B11: =_xlfn.XLOOKUP(A11, scored_company_data!A:A, scored_company_data!AF:AF, "Brak firmy") -> 81.68 | C11: 9 | E11: =A11 -> 840 | F11: =_xlfn.XLOOKUP(A11, scored_27_rules!A:A, scored_27_rules!AF:AF, "Brak firmy") -> 73.1 | G11: =MATCH(E11, scored_27_rules!A:A, 0) - 1 -> 63 | K11: 27 | L11: =_xlfn.XLOOKUP(K11, scored_27_rules!A:A, scored_27_rules!AF:AF, "Brak firmy") -> 80.21 | M11: 9 | O11: 27 | P11: =_xlfn.XLOOKUP(O11, scored_company_data!A:A, scored_company_data!AF:AF, "Brak firmy") -> 61.95 | Q11: =MATCH(O11, scored_company_data!A:A, 0) - 1 -> 151
A12: 439 | B12: =_xlfn.XLOOKUP(A12, scored_company_data!A:A, scored_company_data!AF:AF, "Brak firmy") -> 81.22 | C12: 10 | E12: =A12 -> 439 | F12: =_xlfn.XLOOKUP(A12, scored_27_rules!A:A, scored_27_rules!AF:AF, "Brak firmy") -> 72.35 | G12: =MATCH(E12, scored_27_rules!A:A, 0) - 1 -> 77 | K12: 62 | L12: =_xlfn.XLOOKUP(K12, scored_27_rules!A:A, scored_27_rules!AF:AF, "Brak firmy") -> 80.2 | M12: 10 | O12: 62 | P12: =_xlfn.XLOOKUP(O12, scored_company_data!A:A, scored_company_data!AF:AF, "Brak firmy") -> 62.21 | Q12: =MATCH(O12, scored_company_data!A:A, 0) - 1 -> 145
A14: Scored Company data last10 | E14: scored_27_results - comparisson | K14: Scored_27_results last10 | O14: Scored Company data - comparisson
A15: CompanyID | B15: Target Score | C15: placement | E15: CompanyID | F15: Target Score | G15: placement | K15: CompanyID | L15: Target Score | M15: placement | O15: CompanyID | P15: Target Score | Q15: placement
A16: 713 | B16: =_xlfn.XLOOKUP(A16, scored_company_data!A:A, scored_company_data!AF:AF, "Brak firmy") -> 17.17 | C16: 1000 | E16: =A16 -> 713 | F16: =_xlfn.XLOOKUP(E16, scored_27_rules!A:A, scored_27_rules!AF:AF, "Brak firmy") -> 17.48 | G16: =MATCH(E16, scored_27_rules!A:A, 0) - 1 -> 999 | K16: 31 | L16: =_xlfn.XLOOKUP(K16, scored_27_rules!A:A, scored_27_rules!AF:AF, "Brak firmy") -> 16.93 | M16: 1000 | O16: 31 | P16: =_xlfn.XLOOKUP(O16, scored_company_data!A:A, scored_company_data!AF:AF, "Brak firmy") -> 18.94 | Q16: =MATCH(O16, scored_company_data!A:A, 0) - 1 -> 998
A17: 354 | B17: =_xlfn.XLOOKUP(A17, scored_company_data!A:A, scored_company_data!AF:AF, "Brak firmy") -> 17.54 | C17: 999 | E17: =A17 -> 354 | F17: =_xlfn.XLOOKUP(E17, scored_27_rules!A:A, scored_27_rules!AF:AF, "Brak firmy") -> 17.72 | G17: =MATCH(E17, scored_27_rules!A:A, 0) - 1 -> 998 | K17: 713 | L17: =_xlfn.XLOOKUP(K17, scored_27_rules!A:A, scored_27_rules!AF:AF, "Brak firmy") -> 17.48 | M17: 999 | O17: 713 | P17: =_xlfn.XLOOKUP(O17, scored_company_data!A:A, scored_company_data!AF:AF, "Brak firmy") -> 17.17 | Q17: =MATCH(O17, scored_company_data!A:A, 0) - 1 -> 1000
A18: 31 | B18: =_xlfn.XLOOKUP(A18, scored_company_data!A:A, scored_company_data!AF:AF, "Brak firmy") -> 18.94 | C18: 998 | E18: =A18 -> 31 | F18: =_xlfn.XLOOKUP(E18, scored_27_rules!A:A, scored_27_rules!AF:AF, "Brak firmy") -> 16.93 | G18: =MATCH(E18, scored_27_rules!A:A, 0) - 1 -> 1000 | K18: 354 | L18: =_xlfn.XLOOKUP(K18, scored_27_rules!A:A, scored_27_rules!AF:AF, "Brak firmy") -> 17.72 | M18: 998 | O18: 354 | P18: =_xlfn.XLOOKUP(O18, scored_company_data!A:A, scored_company_data!AF:AF, "Brak firmy") -> 17.54 | Q18: =MATCH(O18, scored_company_data!A:A, 0) - 1 -> 999
A19: 615 | B19: =_xlfn.XLOOKUP(A19, scored_company_data!A:A, scored_company_data!AF:AF, "Brak firmy") -> 20.22 | C19: 997 | E19: =A19 -> 615 | F19: =_xlfn.XLOOKUP(E19, scored_27_rules!A:A, scored_27_rules!AF:AF, "Brak firmy") -> 32.26 | G19: =MATCH(E19, scored_27_rules!A:A, 0) - 1 -> 978 | K19: 43 | L19: =_xlfn.XLOOKUP(K19, scored_27_rules!A:A, scored_27_rules!AF:AF, "Brak firmy") -> 17.96 | M19: 997 | O19: 43 | P19: =_xlfn.XLOOKUP(O19, scored_company_data!A:A, scored_company_data!AF:AF, "Brak firmy") -> 23.06 | Q19: =MATCH(O19, scored_company_data!A:A, 0) - 1 -> 990
A20: 492 | B20: =_xlfn.XLOOKUP(A20, scored_company_data!A:A, scored_company_data!AF:AF, "Brak firmy") -> 20.88 | C20: 996 | E20: =A20 -> 492 | F20: =_xlfn.XLOOKUP(E20, scored_27_rules!A:A, scored_27_rules!AF:AF, "Brak firmy") -> 19.83 | G20: =MATCH(E20, scored_27_rules!A:A, 0) - 1 -> 996 | K20: 492 | L20: =_xlfn.XLOOKUP(K20, scored_27_rules!A:A, scored_27_rules!AF:AF, "Brak firmy") -> 19.83 | M20: 996 | O20: 492 | P20: =_xlfn.XLOOKUP(O20, scored_company_data!A:A, scored_company_data!AF:AF, "Brak firmy") -> 20.88 | Q20: =MATCH(O20, scored_company_data!A:A, 0) - 1 -> 996
A21: 91 | B21: =_xlfn.XLOOKUP(A21, scored_company_data!A:A, scored_company_data!AF:AF, "Brak firmy") -> 20.99 | C21: 995 | E21: =A21 -> 91 | F21: =_xlfn.XLOOKUP(E21, scored_27_rules!A:A, scored_27_rules!AF:AF, "Brak firmy") -> 36.24 | G21: =MATCH(E21, scored_27_rules!A:A, 0) - 1 -> 965 | K21: 96 | L21: =_xlfn.XLOOKUP(K21, scored_27_rules!A:A, scored_27_rules!AF:AF, "Brak firmy") -> 20.1 | M21: 995 | O21: 96 | P21: =_xlfn.XLOOKUP(O21, scored_company_data!A:A, scored_company_data!AF:AF, "Brak firmy") -> 23.69 | Q21: =MATCH(O21, scored_company_data!A:A, 0) - 1 -> 988
A22: 390 | B22: =_xlfn.XLOOKUP(A22, scored_company_data!A:A, scored_company_data!AF:AF, "Brak firmy") -> 21.25 | C22: 994 | E22: =A22 -> 390 | F22: =_xlfn.XLOOKUP(E22, scored_27_rules!A:A, scored_27_rules!AF:AF, "Brak firmy") -> 36.58 | G22: =MATCH(E22, scored_27_rules!A:A, 0) - 1 -> 961 | K22: 114 | L22: =_xlfn.XLOOKUP(K22, scored_27_rules!A:A, scored_27_rules!AF:AF, "Brak firmy") -> 24.2 | M22: 994 | O22: 114 | P22: =_xlfn.XLOOKUP(O22, scored_company_data!A:A, scored_company_data!AF:AF, "Brak firmy") -> 30.12 | Q22: =MATCH(O22, scored_company_data!A:A, 0) - 1 -> 891
A23: 461 | B23: =_xlfn.XLOOKUP(A23, scored_company_data!A:A, scored_company_data!AF:AF, "Brak firmy") -> 22.02 | C23: 993 | E23: =A23 -> 461 | F23: =_xlfn.XLOOKUP(E23, scored_27_rules!A:A, scored_27_rules!AF:AF, "Brak firmy") -> 38.61 | G23: =MATCH(E23, scored_27_rules!A:A, 0) - 1 -> 931 | K23: 6 | L23: =_xlfn.XLOOKUP(K23, scored_27_rules!A:A, scored_27_rules!AF:AF, "Brak firmy") -> 24.46 | M23: 993 | O23: 6 | P23: =_xlfn.XLOOKUP(O23, scored_company_data!A:A, scored_company_data!AF:AF, "Brak firmy") -> 23.33 | Q23: =MATCH(O23, scored_company_data!A:A, 0) - 1 -> 989
A24: 564 | B24: =_xlfn.XLOOKUP(A24, scored_company_data!A:A, scored_company_data!AF:AF, "Brak firmy") -> 22.21 | C24: 992 | E24: =A24 -> 564 | F24: =_xlfn.XLOOKUP(E24, scored_27_rules!A:A, scored_27_rules!AF:AF, "Brak firmy") -> 39.26 | G24: =MATCH(E24, scored_27_rules!A:A, 0) - 1 -> 928 | K24: 952 | L24: =_xlfn.XLOOKUP(K24, scored_27_rules!A:A, scored_27_rules!AF:AF, "Brak firmy") -> 24.67 | M24: 992 | O24: 952 | P24: =_xlfn.XLOOKUP(O24, scored_company_data!A:A, scored_company_data!AF:AF, "Brak firmy") -> 23.9 | Q24: =MATCH(O24, scored_company_data!A:A, 0) - 1 -> 986
A25: 759 | B25: =_xlfn.XLOOKUP(A25, scored_company_data!A:A, scored_company_data!AF:AF, "Brak firmy") -> 22.68 | C25: 991 | E25: =A25 -> 759 | F25: =_xlfn.XLOOKUP(E25, scored_27_rules!A:A, scored_27_rules!AF:AF, "Brak firmy") -> 47.0 | G25: =MATCH(E25, scored_27_rules!A:A, 0) - 1 -> 853 | K25: 701 | L25: =_xlfn.XLOOKUP(K25, scored_27_rules!A:A, scored_27_rules!AF:AF, "Brak firmy") -> 25.08 | M25: 991 | O25: 701 | P25: =_xlfn.XLOOKUP(O25, scored_company_data!A:A, scored_company_data!AF:AF, "Brak firmy") -> 31.76 | Q25: =MATCH(O25, scored_company_data!A:A, 0) - 1 -> 795
